Workbook

Sheet Historique
B1: En millions | G1: Répartition par canton
B2: Bénéfice | C2: Chiffre affaires (OFJ) | D2: RBJ | E2: PBJ | F2: Source | G2: FR | H2: VD | I2: GE | J2: NE | K2: VS | L2: JU | M2: N° | N2: Note
A3: 1938 | B3: =1.154942+0.56164264+0.412947 -> 2.1295316 | E3: =0.95494+0.56164264 -> 1.5165826 | F3: Courrier de Genève, Volume 71, Numéro 29, 30 janvier 1938, L'impartial, 16 juillet 1938, La Gruyère, 17 septembre 1938 | G3: =105676+74677.32 -> 180353.32 | H3: =388438+203986 -> 592424 | I3: =176267+123099+80041 -> 379407 | J3: =176693+100868 -> 277561 | K3: =107866+59010+47655 -> 214531 | M3: 46082 | N3: première loterie
A4: 1939
A5: 1940 | C5: 9 | F5: OFJ
A6: 1941
A7: 1942
A8: 1943
A9: 1944
A10: 1945
A11: 1946
A12: 1947
A13: 1948
A14: 1949
A15: 1950 | C15: 6.2 | F15: OFJ
A16: 1951
A17: 1952
A18: 1953
A19: 1954
A20: 1955
A21: 1956
A22: 1957
A23: 1958
A24: 1959
A25: 1960 | C25: 7.8 | F25: OFJ
A26: 1961
A27: 1962
A28: 1963
A29: 1964
A30: 1965
A31: 1966
A32: 1967
A33: 1968
A34: 1969
A35: 1970 | C35: 10.68 | F35: OFJ
A36: 1971
A37: 1972
A38: 1973
A39: 1974
A40: 1975
...

Sheet Total
C1: 2000 | D1: 2001 | E1: 2002 | F1: 2003 | G1: 2004 | H1: 2005 | I1: 2006 | J1: 2007 | K1: 2008 | L1: 2009 | M1: 2010 | N1: 2011 | O1: 2012 | P1: 2013 | Q1: 2014 | R1: 2015 | S1: 2016 | T1: 2017 | U1: 2018 | V1: 2019 | W1: 2020 | X1: 2021 | Y1: 2022 | Z1: 2023 | AA1: 2024 | AB1: 2025
B2: Produit brut des jeux en Suisse (milions) | C2: =If(C5+C29+C37=0, " ",C5+C29+C37) | D2: =If(D5+D29+D37=0, " ",D5+D29+D37) | E2: =If(E5+E29+E37=0, " ",E5+E29+E37) | F2: =If(F5+F29+F37=0, " ",F5+F29+F37) -> 421 | G2: =If(G5+G29+G37=0, " ",G5+G29+G37) -> 489 | H2: =If(H5+H29+H37=0, " ",H5+H29+H37) -> 548 | I2: =If(I5+I29+I37=0, " ",I5+I29+I37) -> 582 | J2: =If(J5+J29+J37=0, " ",J5+J29+J37) -> 532 | ... AB2: =If(AB5+AB29+AB37=0, " ",AB5+AB29+AB37) -> 429.82499
B3: Distribué aux cantons, confédération etc. | C3: =if(C8+C31+C43=0, " ",C8+C31+C43) | D3: =if(D8+D31+D43=0, " ",D8+D31+D43) | E3: =if(E8+E31+E43=0, " ",E8+E31+E43) | F3: =if(F8+F31+F43=0, " ",F8+F31+F43) | G3: =if(G8+G31+G43=0, " ",G8+G31+G43) -> 172 | H3: =if(H8+H31+H43=0, " ",H8+H31+H43) -> 178.4 | I3: =if(I8+I31+I43=0, " ",I8+I31+I43) -> 188.5 | J3: =if(J8+J31+J43=0, " ",J8+J31+J43) -> 174.2 | ... AB3: =if(AB8+AB31+AB43=0, " ",AB8+AB31+AB43) -> 252.00529
A5: Loro | B5: Produit brut des jeux (milions) | L5: 371 | M5: 358 | N5: 370 | O5: 367.02483 | P5: ='Détail'!P8/1000000 -> 377.73526 | Q5: ='Détail'!P17/1000000 -> 387.64197 | R5: ='Détail'!P26/1000000 -> 376.82264 | S5: ='Détail'!P35/1000000 -> 398.33907 | T5: ='Détail'!P44/1000000 -> 386.48654 | U5: ='Détail'!P53/1000000 -> 387.96252 | V5: ='Détail'!P62/1000000 -> 408.05763 | W5: ='Détail'!P71/1000000 -> 374.28789 | X5: ='Détail'!P80/1000000 -> 396.99127 | Y5: ='Détail'!P89/1000000 -> 435.48415 | Z5: ='Détail'!P98/1000000 -> 420.70802 | AA5: ='Détail'!P107/1000000 -> 438.23525 | AB5: ='Détail'!P116/1000000 -> 429.82499
B6: % produit brut des jeux réalisé en points de vente | AA6: 84.6 | AB6: 81.4
B7: % produit brut des jeux réalisé sur la plateforme en ligne | AA7: 15.4 | AB7: =100-AB6 -> 18.6
B8: Bénéfice (milions) | G8: 172 | H8: 178.4 | I8: 188.5 | J8: 174.2 | K8: 183.2 | L8: 190.7 | M8: 198.7 | N8: 203.3 | O8: 203 | P8: 206 | Q8: 209.9 | R8: 209.5 | S8: 216.8 | T8: 216.2 | U8: 216.4 | V8: 224.3 | W8: 224.7 | X8: 235 | Y8: 243.4 | Z8: 243.7 | AA8: 258.23616 | AB8: 252.00529
B10: Commission pour les points de vente (milions) | O10: 68.120081 | P10: 69.596211 | Q10: 71.874502 | R10: 70.463545 | S10: 74.5 | T10: 71.6 | U10: 71.883425 | V10: 75.876415 | W10: 70.078282 | X10: 75.00421 | Y10: 80.909395 | Z10: 79.966479 | AA10: 79.386684 | AB10: 79.196622
B11: cafés et restaurants (nombre) | AA11: 734 | AB11: 707
B12: kiosques (nombre) | AA12: 739 | AB12: 733
B13: commerces (nombre) | AA13: 898 | AB13: 902
B14: total (nombre) | P14: 2651 | Q14: 2651 | R14: 2651 | S14: 2601 | T14: 2601 | U14: 2501 | V14: 2451 | W14: 2400 | X14: 2400 | Y14: 2400 | Z14: 2359 | AA14: 2371 | AB14: 2342
B15: Commission moyenne | P15: =P10*1000000/P14 -> 26252.814 | Q15: =Q10*1000000/Q14 -> 27112.223 | R15: =R10*1000000/R14 -> 26579.987 | S15: =S10*1000000/S14 -> 28642.83 | T15: =T10*1000000/T14 -> 27527.874 | U15: =U10*1000000/U14 -> 28741.873 | V15: =V10*1000000/V14 -> 30957.33 | W15: =W10*1000000/W14 -> 29199.284 | ... AB15: =AB10*1000000/AB14 -> 33815.808
B17: Rémunération de la Direction (milions) | W17: 2.24965 | X17: 2.274249 | Y17: 2.37152 | Z17: 2.312064 | AA17: 2.287502 | AB17: 2.241173
B18: EPT Direction | W18: 9.7 | X18: 9.8 | Y18: 9.7 | Z18: 9.2 | AA18: 9.2 | AB18: 8.9
B19: Salaire moyen mensuel direction | W19: =((W17*1000000)/W18)/13 -> 17840.206 | X19: =((X17*1000000)/X18)/13 -> 17851.248 | Y19: =((Y17*1000000)/Y18)/13 -> 18806.661 | Z19: =((Z17*1000000)/Z18)/13 -> 19331.639 | AA19: =((AA17*1000000)/AA18)/13 -> 19126.271 | AB19: =((AB17*1000000)/AB18)/13 -> 19370.553
B20: Marketing, publicité et communication (milions) | O20: 16.336196 | P20: 15.230183 | Q20: 15.23539 | R20: 13.817968 | S20: 13.742552 | T20: 14.041487 | U20: 14.141136 | V20: 13.411041 | W20: 11.219172 | X20: 11.374329 | Y20: 13.264486 | Z20: 13.00049 | AA20: 15.354708 | AB20: 13.925272
B22: Fondation suisse pour lencouragement du sport (FSES) - en millions | P22: 6.481835 | Q22: 10.30562 | R22: 6.592762 | S22: 10.650175 | T22: 10.63213 | U22: 10.652251 | V22: 11.051532 | W22: 11.082441 | X22: 11.599846 | Y22: 19.507412 | Z22: 19.519996 | AA22: 19.567627 | AB22: 19.608735
B23: Fédération suisse de courses de chevaux (FSC) | P23: 3.742702 | Q23: 3.832166 | R23: 3.829008 | S23: 3.752897 | T23: 3.573387 | U23: 3.387602 | V23: 3.313814 | W23: 3.030524 | X23: 3.043011 | Y23: 3.434566 | Z23: 3.420448 | AA23: 3.2342 | AB23: 2.870533
B25: Prévention du jeu excessif (milions) | P25: 1.888676 | Q25: 1.93821 | R25: 1.884113 | S25: 1.99 | T25: 1.932433 | U25: 1.939813 | V25: 2.040288 | W25: 1.87 | X25: 1.984956 | Y25: 2.177421 | Z25: 2.10354 | AA25: 2.191176 | AB25: 2.149125
B26: Joueurs en ligne | AA26: 174000 | AB26: 180000
B27: Contrôles des mesures de protection des joueuses et joueurs via des clients mystères dans les points de vente (nombre) | W27: 1715 | X27: 1266 | Y27: 2838 | Z27: 2831 | AA27: 2944 | AB27: 2959
A29: Swisslos | B29: Produit brut des jeux (milions) Bruttospielertrag | F29: 421 | G29: 489 | H29: 548 | I29: 582 | J29: 532 | K29: 530 | L29: 528.2244 | M29: 504.4281 | N29: 533.53136 | O29: 532.23901 | P29: 533.59183 | Q29: 568.33109 | R29: 518.56345 | S29: 598.73917 | T29: 553.46184 | U29: 555.39982 | V29: 594.73646 | W29: 620.02534 | X29: 699.49323 | Y29: 736.5424 | Z29: 738.15311 | AA29: 812.10699
B30: Prévention du jeu excessif (milions) Spielsuchtabgabe | P30: 2.684662 | Q30: 2.857357 | R30: 2.582677 | S30: 2.981379 | T30: 2.770326 | U30: 2.764488 | V30: 2.977186 | W30: 3.080985 | X30: 3.482176 | Y30: 3.674887 | Z30: 4.050498 | AA30: 3.683054
B31: Auszahlung an die Kantone | L31: 325.51389 | M31: 316.83569 | N31: 327.118 | O31: 325.95419 | P31: 336.97984 | Q31: 359.79858 | R31: 327.66866 | S31: 368.61025 | T31: 339.39147 | U31: 331.99248 | V31: 362.3228 | W31: 383.02558 | X31: 437.84184 | Y31: 434.23708 | Z31: 455.37004 | AA31: 540.05376
A33: CFMJ | B33: Produit brut des jeux (milions) - Casino A | L33: 553.53386 | M33: 524.15143 | N33: 494.5525 | O33: 451.21275 | P33: 449.56098 | Q33: 426.20628 | R33: 408.84793 | S33: 412.68357 | T33: 410.79168 | U33: 426.38237 | V33: 448.96273 | W33: 284.5886 | X33: 246.07185 | Y33: 375.12229 | Z33: 365.34936 | AA33: 341.07585
B34: Produit brut des jeux (milions) - Casino B | L34: 382.78364 | M34: 344.58586 | N34: 330.23716 | O34: 306.31234 | P34: 296.6069 | Q34: 283.60563 | R34: 273.31302 | S34: 277.04637 | T34: 270.01875 | U34: 277.2167 | V34: 293.49191 | W34: 167.37776 | X34: 159.72614 | Y34: 254.44867 | Z34: 258.50741 | AA34: 246.45555
B35: Produit brut des jeux (milions) - Total | C35: =if(C33+C34=0,"",C33+C34) | D35: =if(D33+D34=0,"",D33+D34) | E35: =if(E33+E34=0,"",E33+E34) | F35: =if(F33+F34=0,"",F33+F34) | G35: =if(G33+G34=0,"",G33+G34) | H35: =if(H33+H34=0,"",H33+H34) | I35: =if(I33+I34=0,"",I33+I34) | J35: =if(J33+J34=0,"",J33+J34) | ... AA35: =if(AA33+AA34=0,"",AA33+AA34) -> 587.5314
B36: Produit brut des jeux (milions) - Offre en ligne | V36: 23.493714 | W36: 186.81397 | X36: 234.46186 | Y36: 250.05615 | Z36: 285.70665 | AA36: 309.94731
A37: CFMJ | B37: Produit brut des jeux (milions) - FULL | C37: =if(C33+C34+C36=0,"",C33+C34+C36) | D37: =if(D33+D34+D36=0,"",D33+D34+D36) | E37: =if(E33+E34+E36=0,"",E33+E34+E36) | F37: =if(F33+F34+F36=0,"",F33+F34+F36) | G37: =if(G33+G34+G36=0,"",G33+G34+G36) | H37: =if(H33+H34+H36=0,"",H33+H34+H36) | I37: =if(I33+I34+I36=0,"",I33+I34+I36) | J37: =if(J33+J34+J36=0,"",J33+J34+J36) | ... AA37: =if(AA33+AA34+AA36=0,"",AA33+AA34+AA36) -> 897.47871
B39: Impôt sur les maisons de jeu en francs (milions) - Casino A | L39: 296.26155 | M39: 293.09251 | N39: 271.04802 | O39: 237.91769 | P39: 227.76663 | Q39: 212.43774 | R39: 202.53296 | S39: 204.98239 | T39: 204.51291 | U39: 213.66748 | V39: 227.30574 | W39: 129.42044 | X39: 108.90697 | Y39: 181.53583 | Z39: 175.83045 | AA39: 161.70456
B40: Impôt sur les maisons de jeu en francs (milions) - Casino B | L40: 182.72936 | M40: 156.70527 | N40: 148.20655 | O40: 135.70774 | P40: 128.78264 | Q40: 123.61452 | R40: 117.56099 | S40: 118.26818 | T40: 112.38743 | U40: 118.75848 | V40: 129.38104 | W40: 197.74937 | X40: 66.123699 | Y40: 112.2449 | Z40: 113.33211 | AA40: 107.05043
B41: Impôt sur les maisons de jeu en francs (milions) - Offre en ligne | V41: 7.459001 | W41: 78.049199 | X41: 99.680552 | Y41: 103.31838 | Z41: 120.11133 | AA41: 132.09206
B43: Taxes totales des maisons de jeu | C43: =if(C39+C40+C41=0,"",C39+C40+C41) | D43: =if(D39+D40+D41=0,"",D39+D40+D41) | E43: =if(E39+E40+E41=0,"",E39+E40+E41) | F43: =if(F39+F40+F41=0,"",F39+F40+F41) | G43: =if(G39+G40+G41=0,"",G39+G40+G41) | H43: =if(H39+H40+H41=0,"",H39+H40+H41) | I43: =if(I39+I40+I41=0,"",I39+I40+I41) | J43: =if(J39+J40+J41=0,"",J39+J40+J41) | ... AA43: =if(AA39+AA40+AA41=0,"",AA39+AA40+AA41) -> 400.84705
B45: Charges de transfert en faveur de lAVS | N45: 414.88173 | O45: 381.09624 | P45: 376.05386 | Q45: 329.35523 | R45: 307.71177 | S45: 285.32697 | T45: 271.56404 | U45: 273.6466 | V45: 272.26578 | W45: 274.19722 | X45: 305.2 | Y45: 269.04942 | Z45: 342.25131 | AA45: 325.92381

Sheet Détail
A1: Année | B1: Poste | C1: Libellé | D1: VAUD | F1: FRIBOURG | H1: VALAIS | J1: NEUCHÂTEL | L1: GENÈVE | N1: JURA | P1: TOTAL | Q1: Intercantonal | R1: Swisslos | S1: Culture | T1: Santé et handicap | U1: Jeunesse et éducation | V1: Action sociale et personnes âgées | W1: Sport | X1: Promotion, tourisme et développement | Y1: Environnement | Z1: Conservation du patrimoine | AA1: Formation et recherche
A2: 2013 | B2: Répartition | C2: Répartiton | D2: 33217743 | E2: =D2/(D2+H2+J2+L2+N2) -> 0.33493749 | F2: 16904793 | G2: =F2/(D2+F2+H2+J2+L2+N2) -> 0.14562961 | H2: 23832371 | I2: =H2/(D2+F2+J2+L2+N2) -> 0.25835005 | J2: 13286650 | K2: =J2/(D2+F2+H2+J2+L2+N2) -> 0.11446042 | L2: 22938216 | M2: =L2/(D2+F2+H2+J2+L2+N2) -> 0.1976057 | N2: 5900967 | O2: =N2/(D2+F2+H2+J2+L2+N2) -> 0.050835022 | P2: =SUM(D2:N2)+Q2 -> 1.3009274e+08 | Q2: 14012000 | S2: 58129001 | T2: 10098621 | U2: 11407769 | V2: 17927484 | W2: 34334787 | X2: 11009731 | Y2: 2874500 | Z2: 13903934 | AA2: 4741700
A3: 2013 | B3: Vente.1 | C3: Billets Instantanés | D3: 37786290 | E3: =D3/(D3+H3+J3+L3+N3) -> 0.4248003 | F3: 9674862 | G3: =F3/(D3+F3+H3+J3+L3+N3) -> 0.098096887 | H3: 21542305 | I3: =H3/(D3+F3+J3+L3+N3) -> 0.27946797 | J3: 10590107 | K3: =J3/(D3+F3+H3+J3+L3+N3) -> 0.10737688 | L3: 14476400 | M3: =L3/(D3+F3+H3+J3+L3+N3) -> 0.1467814 | N3: 4555612 | O3: =N3/(D3+F3+H3+J3+L3+N3) -> 0.04619098 | P3: =SUM(D3:N3) -> 98625577
A4: 2013 | B4: Vente.2 | C4: Jeux de tirages | D4: 56697217 | E4: =D4/(D4+H4+J4+L4+N4) -> 0.43780109 | F4: 18721542 | G4: =F4/(D4+F4+H4+J4+L4+N4) -> 0.12630399 | H4: 30090248 | I4: =H4/(D4+F4+J4+L4+N4) -> 0.25470896 | J4: 12408056 | K4: =J4/(D4+F4+H4+J4+L4+N4) -> 0.083710358 | L4: 25299785 | M4: =L4/(D4+F4+H4+J4+L4+N4) -> 0.17068379 | N4: 5009206 | O4: =N4/(D4+F4+H4+J4+L4+N4) -> 0.033794369 | P4: =SUM(D4:N4) -> 1.4822606e+08
A5: 2013 | B5: Vente.3 | C5: Paris sportifs | D5: 1695500 | E5: =D5/(D5+H5+J5+L5+N5) -> 0.42493149 | F5: 471569 | G5: =F5/(D5+F5+H5+J5+L5+N5) -> 0.10569447 | H5: 906958 | I5: =H5/(D5+F5+J5+L5+N5) -> 0.25514577 | J5: 423984 | K5: =J5/(D5+F5+H5+J5+L5+N5) -> 0.095029075 | L5: 855890 | M5: =L5/(D5+F5+H5+J5+L5+N5) -> 0.19183374 | N5: 107723 | O5: =N5/(D5+F5+H5+J5+L5+N5) -> 0.024144347 | P5: =SUM(D5:N5) -> 4461625.1
A6: 2013 | B6: Vente.4 | C6: Loterie électronique | D6: 35547603 | E6: =D6/(D6+H6+J6+L6+N6) -> 0.40509504 | F6: 5728975 | G6: =F6/(D6+F6+H6+J6+L6+N6) -> 0.06128541 | H6: 17407418 | I6: =H6/(D6+F6+J6+L6+N6) -> 0.22882571 | J6: 8709996 | K6: =J6/(D6+F6+H6+J6+L6+N6) -> 0.093174726 | L6: 22977976 | M6: =L6/(D6+F6+H6+J6+L6+N6) -> 0.24580569 | N6: 3108275 | O6: =N6/(D6+F6+H6+J6+L6+N6) -> 0.033250609 | P6: =SUM(D6:N6) -> 93480244
A7: 2013 | B7: Vente.5 | C7: PMUR | D7: 13701626 | E7: =D7/(D7+H7+J7+L7+N7) -> 0.43962016 | F7: 1774790 | G7: =F7/(D7+F7+H7+J7+L7+N7) -> 0.053876607 | H7: 4744389 | I7: =H7/(D7+F7+J7+L7+N7) -> 0.16825646 | J7: 4066692 | K7: =J7/(D7+F7+H7+J7+L7+N7) -> 0.12345098 | L7: 6846983 | M7: =L7/(D7+F7+H7+J7+L7+N7) -> 0.20785119 | N7: 1807275 | O7: =N7/(D7+F7+H7+J7+L7+N7) -> 0.054862742 | P7: =SUM(D7:N7) -> 32941756
A8: 2013 | B8: Vente.6 | C8: Total | D8: =SUM(D3:D7) -> 145428236 | E8: =D8/(D8+H8+J8+L8+N8) -> 0.42602162 | F8: =SUM(F3:F7) -> 36371738 | G8: =F8/(D8+F8+H8+J8+L8+N8) -> 0.096288969 | H8: =SUM(H3:H7) -> 74691318 | I8: =H8/(D8+F8+J8+L8+N8) -> 0.24647026 | J8: =SUM(J3:J7) -> 36198835 | K8: =J8/(D8+F8+H8+J8+L8+N8) -> 0.095831233 | L8: =SUM(L3:L7) -> 70457034 | M8: =L8/(D8+F8+H8+J8+L8+N8) -> 0.18652491 | N8: =SUM(N3:N7) -> 14588091 | O8: =N8/(D8+F8+H8+J8+L8+N8) -> 0.038619882 | P8: =SUM(P3:P7) -> 3.7773526e+08 | R8: =Total!P29*1000000 -> 533591829
A9: 2013 | B9: Vente.7 | C9: Point de vente | D9: 968 | E9: =D9/(D9+H9+J9+L9+N9) -> 0.41456103 | F9: 315 | G9: =F9/(D9+F9+H9+J9+L9+N9) -> 0.11886792 | H9: 492 | I9: =H9/(D9+F9+J9+L9+N9) -> 0.22798888 | J9: 272 | K9: =J9/(D9+F9+H9+J9+L9+N9) -> 0.10264151 | L9: 440 | M9: =L9/(D9+F9+H9+J9+L9+N9) -> 0.16603774 | N9: 163 | O9: =N9/(D9+F9+H9+J9+L9+N9) -> 0.061509434 | P9: =SUM(D9:N9) -> 2651.0301
A10: 2013 | B10: Vente.8 | C10: Population | D10: 734356 | E10: =D10/(D10+H10+J10+L10+N10) -> 0.41613999 | F10: 291395 | G10: =F10/(D10+F10+H10+J10+L10+N10) -> 0.14172357 | H10: 321732 | I10: =H10/(D10+F10+J10+L10+N10) -> 0.18550602 | J10: 174554 | K10: =J10/(D10+F10+H10+J10+L10+N10) -> 0.084896502 | L10: 463101 | M10: =L10/(D10+F10+H10+J10+L10+N10) -> 0.22523491 | N10: 70942 | O10: =N10/(D10+F10+H10+J10+L10+N10) -> 0.034503521 | P10: =SUM(D10:N10) -> 2056081.1
A11: 2014 | B11: Répartition | C11: Répartiton | D11: 36880059 | E11: =D11/(D11+H11+J11+L11+N11) -> 0.3424337 | F11: 14672240 | G11: =F11/(D11+F11+H11+J11+L11+N11) -> 0.11989858 | H11: 26149635 | I11: =H11/(D11+F11+J11+L11+N11) -> 0.27176229 | J11: 13549800 | K11: =J11/(D11+F11+H11+J11+L11+N11) -> 0.11072623 | L11: 25764723 | M11: =L11/(D11+F11+H11+J11+L11+N11) -> 0.21054411 | N11: 5355635 | O11: =N11/(D11+F11+H11+J11+L11+N11) -> 0.043765167 | P11: =SUM(D11:N11)+Q11 -> 1.3822674e+08 | Q11: 15854650 | S11: 62505562 | T11: 8559152 | U11: 12703848 | V11: 16892950 | X11: 11969835 | Y11: 2972500 | Z11: 14433704 | AA11: 8189191
A12: 2014 | B12: Vente.1 | C12: Billets Instantanés | D12: 39695036 | E12: =D12/(D12+H12+J12+L12+N12) -> 0.43153559 | F12: 10245764 | G12: =F12/(D12+F12+H12+J12+L12+N12) -> 0.10022139 | H12: 22159564 | I12: =H12/(D12+F12+J12+L12+N12) -> 0.27674637 | J12: 10613518 | K12: =J12/(D12+F12+H12+J12+L12+N12) -> 0.10381867 | L12: 14999555 | M12: =L12/(D12+F12+H12+J12+L12+N12) -> 0.14672174 | N12: 4517870 | O12: =N12/(D12+F12+H12+J12+L12+N12) -> 0.044192627 | P12: =SUM(D12:N12) -> 1.0223131e+08
A13: 2014 | B13: Vente.2 | C13: Jeux de tirages | D13: 58895648 | E13: =D13/(D13+H13+J13+L13+N13) -> 0.43294965 | F13: 19906298 | G13: =F13/(D13+F13+H13+J13+L13+N13) -> 0.12765375 | H13: 31719247 | I13: =H13/(D13+F13+J13+L13+N13) -> 0.25534625 | J13: 12468092 | K13: =J13/(D13+F13+H13+J13+L13+N13) -> 0.079954531 | L13: 27807385 | M13: =L13/(D13+F13+H13+J13+L13+N13) -> 0.1783213 | N13: 5143110 | O13: =N13/(D13+F13+H13+J13+L13+N13) -> 0.032981386 | P13: =SUM(D13:N13) -> 1.5593978e+08
A14: 2014 | B14: Vente.3 | C14: Paris sportifs | D14: 2012567 | E14: =D14/(D14+H14+J14+L14+N14) -> 0.38609709 | F14: 522809 | G14: =F14/(D14+F14+H14+J14+L14+N14) -> 0.091154726 | H14: 1032313 | I14: =H14/(D14+F14+J14+L14+N14) -> 0.2194968 | J14: 584241 | K14: =J14/(D14+F14+H14+J14+L14+N14) -> 0.10186575 | L14: 1474613 | M14: =L14/(D14+F14+H14+J14+L14+N14) -> 0.25710717 | N14: 108859 | O14: =N14/(D14+F14+H14+J14+L14+N14) -> 0.018980187 | P14: =SUM(D14:N14) -> 5735403.1
A15: 2014 | B15: Vente.4 | C15: Loterie électronique | D15: 34956508 | E15: =D15/(D15+H15+J15+L15+N15) -> 0.41573778 | F15: 6107242 | G15: =F15/(D15+F15+H15+J15+L15+N15) -> 0.067715058 | H15: 16137593 | I15: =H15/(D15+F15+J15+L15+N15) -> 0.21792034 | J15: 8472548 | K15: =J15/(D15+F15+H15+J15+L15+N15) -> 0.09394078 | L15: 21510247 | M15: =L15/(D15+F15+H15+J15+L15+N15) -> 0.23849843 | N15: 3006171 | O15: =N15/(D15+F15+H15+J15+L15+N15) -> 0.033331419 | P15: =SUM(D15:N15) -> 90190310
A16: 2014 | B16: Vente.5 | C16: PMUR | D16: 13642064 | E16: =D16/(D16+H16+J16+L16+N16) -> 0.43082784 | F16: 1880398 | G16: =F16/(D16+F16+H16+J16+L16+N16) -> 0.056055705 | H16: 4199916 | I16: =H16/(D16+F16+J16+L16+N16) -> 0.14312081 | J16: 3761548 | K16: =J16/(D16+F16+H16+J16+L16+N16) -> 0.11213383 | L16: 8267234 | M16: =L16/(D16+F16+H16+J16+L16+N16) -> 0.24645082 | N16: 1794007 | O16: =N16/(D16+F16+H16+J16+L16+N16) -> 0.053480342 | P16: =SUM(D16:N16) -> 33545168
A17: 2014 | B17: Vente.6 | C17: Total | D17: =SUM(D12:D16) -> 149201823 | E17: =D17/(D17+H17+J17+L17+N17) -> 0.42753756 | F17: =SUM(F12:F16) -> 38662511 | G17: =F17/(D17+F17+H17+J17+L17+N17) -> 0.099737682 | H17: =SUM(H12:H16) -> 75248633 | I17: =H17/(D17+F17+J17+L17+N17) -> 0.24087785 | J17: =SUM(J12:J16) -> 35899947 | K17: =J17/(D17+F17+H17+J17+L17+N17) -> 0.092611095 | L17: =SUM(L12:L16) -> 74059034 | M17: =L17/(D17+F17+H17+J17+L17+N17) -> 0.19105009 | N17: =SUM(N12:N16) -> 14570017 | O17: =N17/(D17+F17+H17+J17+L17+N17) -> 0.037586274 | P17: =SUM(P12:P16) -> 3.8764197e+08 | R17: =Total!Q29*1000000 -> 568331094
A18: 2014 | B18: Vente.7 | C18: Point de vente | D18: 983 | E18: =D18/(D18+H18+J18+L18+N18) -> 0.41972673 | F18: 308 | G18: =F18/(D18+F18+H18+J18+L18+N18) -> 0.11622642 | H18: 504 | I18: =H18/(D18+F18+J18+L18+N18) -> 0.23485555 | J18: 265 | K18: =J18/(D18+F18+H18+J18+L18+N18) -> 0.1 | L18: 433 | M18: =L18/(D18+F18+H18+J18+L18+N18) -> 0.16339623 | N18: 157 | O18: =N18/(D18+F18+H18+J18+L18+N18) -> 0.059245283 | P18: =SUM(D18:N18) -> 2651.0342
A19: 2014 | B19: Vente.8 | C19: Population | D19: 749373 | E19: =D19/(D19+H19+J19+L19+N19) -> 0.41772071 | F19: 297622 | G19: =F19/(D19+F19+H19+J19+L19+N19) -> 0.14229537 | H19: 327011 | I19: =H19/(D19+F19+J19+L19+N19) -> 0.18532071 | J19: 176402 | K19: =J19/(D19+F19+H19+J19+L19+N19) -> 0.084339152 | L19: 469433 | M19: =L19/(D19+F19+H19+J19+L19+N19) -> 0.22443953 | N19: 71738 | O19: =N19/(D19+F19+H19+J19+L19+N19) -> 0.034298489 | P19: =SUM(D19:N19) -> 2091580.1
A20: 2015 | B20: Répartition | C20: Répartiton | D20: 34153502 | E20: =D20/(D20+H20+J20+L20+N20) -> 0.31686526 | F20: 14478414 | G20: =F20/(D20+F20+H20+J20+L20+N20) -> 0.11841929 | H20: 23251870 | I20: =H20/(D20+F20+J20+L20+N20) -> 0.23483865 | J20: 12954500 | K20: =J20/(D20+F20+H20+J20+L20+N20) -> 0.10595516 | L20: 32285500 | M20: =L20/(D20+F20+H20+J20+L20+N20) -> 0.26406387 | N20: 5140195 | O20: =N20/(D20+F20+H20+J20+L20+N20) -> 0.042041777 | P20: =SUM(D20:N20)+Q20 -> 135392982 | Q20: 13129000 | S20: 62417400 | T20: 15413320 | U20: 12284385 | V20: 19371167 | W20: 34284209 | X20: 8615900 | Y20: 1782500 | Z20: 11910114 | AA20: 2363500
A21: 2015 | B21: Vente.1 | C21: Billets Instantanés | D21: 40763211 | E21: =D21/(D21+H21+J21+L21+N21) -> 0.43136412 | F21: 10648139 | G21: =F21/(D21+F21+H21+J21+L21+N21) -> 0.10126953 | H21: 22447054 | I21: =H21/(D21+F21+J21+L21+N21) -> 0.27142925 | J21: 11078348 | K21: =J21/(D21+F21+H21+J21+L21+N21) -> 0.10536105 | L21: 15580462 | M21: =L21/(D21+F21+H21+J21+L21+N21) -> 0.14817858 | N21: 4629305 | O21: =N21/(D21+F21+H21+J21+L21+N21) -> 0.044027183 | P21: =SUM(D21:N21) -> 1.0514652e+08
A22: 2015 | B22: Vente.2 | C22: Jeux de tirages | D22: 53815199 | E22: =D22/(D22+H22+J22+L22+N22) -> 0.43139061 | F22: 18525390 | G22: =F22/(D22+F22+H22+J22+L22+N22) -> 0.12930081 | H22: 29101367 | I22: =H22/(D22+F22+J22+L22+N22) -> 0.25489009 | J22: 11488057 | K22: =J22/(D22+F22+H22+J22+L22+N22) -> 0.080182659 | L22: 25335412 | M22: =L22/(D22+F22+H22+J22+L22+N22) -> 0.1768324 | N22: 5008159 | O22: =N22/(D22+F22+H22+J22+L22+N22) -> 0.034955215 | P22: =SUM(D22:N22) -> 1.4327359e+08
A23: 2015 | B23: Vente.3 | C23: Paris sportifs | D23: 1968012 | E23: =D23/(D23+H23+J23+L23+N23) -> 0.36910927 | F23: 755147 | G23: =F23/(D23+F23+H23+J23+L23+N23) -> 0.12406032 | H23: 1057744 | I23: =H23/(D23+F23+J23+L23+N23) -> 0.21032095 | J23: 531674 | K23: =J23/(D23+F23+H23+J23+L23+N23) -> 0.087346766 | L23: 1635037 | M23: =L23/(D23+F23+H23+J23+L23+N23) -> 0.26861422 | N23: 139320 | O23: =N23/(D23+F23+H23+J23+L23+N23) -> 0.02288837 | P23: =SUM(D23:N23) -> 6086935.1
A24: 2015 | B24: Vente.4 | C24: Loterie électronique | D24: 34591001 | E24: =D24/(D24+H24+J24+L24+N24) -> 0.41730399 | F24: 6007804 | G24: =F24/(D24+F24+H24+J24+L24+N24) -> 0.06757979 | H24: 15763731 | I24: =H24/(D24+F24+J24+L24+N24) -> 0.21554089 | J24: 8277465 | K24: =J24/(D24+F24+H24+J24+L24+N24) -> 0.093110452 | L24: 21224516 | M24: =L24/(D24+F24+H24+J24+L24+N24) -> 0.23874752 | N24: 3034901 | O24: =N24/(D24+F24+H24+J24+L24+N24) -> 0.034138592 | P24: =SUM(D24:N24) -> 88899419
A25: 2015 | B25: Vente.5 | C25: PMUR | D25: 13168548 | E25: =D25/(D25+H25+J25+L25+N25) -> 0.41829797 | F25: 1934921 | G25: =F25/(D25+F25+H25+J25+L25+N25) -> 0.057903711 | H25: 4066547 | I25: =H25/(D25+F25+J25+L25+N25) -> 0.13855528 | J25: 3509440 | K25: =J25/(D25+F25+H25+J25+L25+N25) -> 0.10502217 | L25: 9076286 | M25: =L25/(D25+F25+H25+J25+L25+N25) -> 0.27161349 | N25: 1660441 | O25: =N25/(D25+F25+H25+J25+L25+N25) -> 0.049689727 | P25: =SUM(D25:N25) -> 33416184
A26: 2015 | B26: Vente.6 | C26: Total | D26: =SUM(D21:D25) -> 144305971 | E26: =D26/(D26+H26+J26+L26+N26) -> 0.42574257 | F26: =SUM(F21:F25) -> 37871401 | G26: =F26/(D26+F26+H26+J26+L26+N26) -> 0.10050193 | H26: =SUM(H21:H25) -> 72436443 | I26: =H26/(D26+F26+J26+L26+N26) -> 0.23797545 | J26: =SUM(J21:J25) -> 34884984 | K26: =J26/(D26+F26+H26+J26+L26+N26) -> 0.092576667 | L26: =SUM(L21:L25) -> 72851713 | M26: =L26/(D26+F26+H26+J26+L26+N26) -> 0.19333157 | N26: =SUM(N21:N25) -> 14472126 | O26: =N26/(D26+F26+H26+J26+L26+N26) -> 0.03840567 | P26: =SUM(P21:P25) -> 3.7682264e+08 | R26: =Total!R29*1000000 -> 518563445
A27: 2015 | B27: Vente.7 | C27: Point de vente | D27: 983 | E27: =D27/(D27+H27+J27+L27+N27) -> 0.41972673 | F27: 308 | G27: =F27/(D27+F27+H27+J27+L27+N27) -> 0.11622642 | H27: 504 | I27: =H27/(D27+F27+J27+L27+N27) -> 0.23485555 | J27: 265 | K27: =J27/(D27+F27+H27+J27+L27+N27) -> 0.1 | L27: 433 | M27: =L27/(D27+F27+H27+J27+L27+N27) -> 0.16339623 | N27: 157 | O27: =N27/(D27+F27+H27+J27+L27+N27) -> 0.059245283 | P27: =SUM(D27:N27) -> 2651.0342
A28: 2015 | B28: Vente.8 | C28: Population | D28: 761446 | E28: =D28/(D28+H28+J28+L28+N28) -> 0.41830085 | F28: 303377 | G28: =F28/(D28+F28+H28+J28+L28+N28) -> 0.1428525 | H28: 331763 | I28: =H28/(D28+F28+J28+L28+N28) -> 0.18514128 | J28: 177327 | K28: =J28/(D28+F28+H28+J28+L28+N28) -> 0.083498767 | L28: 477385 | M28: =L28/(D28+F28+H28+J28+L28+N28) -> 0.22478844 | N28: 72410 | O28: =N28/(D28+F28+H28+J28+L28+N28) -> 0.034096025 | P28: =SUM(D28:N28) -> 2123709.1
A29: 2016 | B29: Répartition | C29: Répartiton | D29: 34846396 | E29: =D29/(D29+H29+J29+L29+N29) -> 0.3237332 | F29: 17316651 | G29: =F29/(D29+F29+H29+J29+L29+N29) -> 0.13858211 | H29: 25143905 | I29: =H29/(D29+F29+J29+L29+N29) -> 0.25191268 | J29: 13302310 | K29: =J29/(D29+F29+H29+J29+L29+N29) -> 0.10645604 | L29: 28579210 | M29: =L29/(D29+F29+H29+J29+L29+N29) -> 0.22871439 | N29: 5767420 | O29: =N29/(D29+F29+H29+J29+L29+N29) -> 0.046155647 | P29: =SUM(D29:N29)+Q29 -> 136853193 | Q29: 11897300 | S29: 66764794 | T29: 8716060 | U29: 12591383 | V29: 20110251 | W29: 35500584 | X29: 7000000 | Y29: 2337760 | Z29: 15390944 | AA29: 3942000
A30: 2016 | B30: Vente.1 | C30: Billets Instantanés | D30: 43254073 | E30: =D30/(D30+H30+J30+L30+N30) -> 0.43232558 | F30: 11488184 | G30: =F30/(D30+F30+H30+J30+L30+N30) -> 0.10299799 | H30: 23805549 | I30: =H30/(D30+F30+J30+L30+N30) -> 0.27134273 | J30: 11640310 | K30: =J30/(D30+F30+H30+J30+L30+N30) -> 0.10436188 | L30: 16619613 | M30: =L30/(D30+F30+H30+J30+L30+N30) -> 0.14900411 | N30: 4730220 | O30: =N30/(D30+F30+H30+J30+L30+N30) -> 0.042409064 | P30: =SUM(D30:N30) -> 1.1153795e+08
A31: 2016 | B31: Vente.2 | C31: Jeux de tirages | D31: 58413917 | E31: =D31/(D31+H31+J31+L31+N31) -> 0.42782883 | F31: 20620419 | G31: =F31/(D31+F31+H31+J31+L31+N31) -> 0.13120976 | H31: 32242070 | I31: =H31/(D31+F31+J31+L31+N31) -> 0.258114 | J31: 12316429 | K31: =J31/(D31+F31+H31+J31+L31+N31) -> 0.078370652 | L31: 27896991 | M31: =L31/(D31+F31+H31+J31+L31+N31) -> 0.17751131 | N31: 5666311 | O31: =N31/(D31+F31+H31+J31+L31+N31) -> 0.036055296 | P31: =SUM(D31:N31) -> 1.5715614e+08
A32: 2016 | B32: Vente.3 | C32: Paris sportifs | D32: 2388859 | E32: =D32/(D32+H32+J32+L32+N32) -> 0.37883652 | F32: 829119 | G32: =F32/(D32+F32+H32+J32+L32+N32) -> 0.11620616 | H32: 1262788 | I32: =H32/(D32+F32+J32+L32+N32) -> 0.21504846 | J32: 578160 | K32: =J32/(D32+F32+H32+J32+L32+N32) -> 0.081032704 | L32: 1917234 | M32: =L32/(D32+F32+H32+J32+L32+N32) -> 0.26871222 | N32: 158737 | O32: =N32/(D32+F32+H32+J32+L32+N32) -> 0.022247974 | P32: =SUM(D32:N32) -> 7134898.1
A33: 2016 | B33: Vente.4 | C33: Loterie électronique | D33: 35064098 | E33: =D33/(D33+H33+J33+L33+N33) -> 0.41939823 | F33: 6263815 | G33: =F33/(D33+F33+H33+J33+L33+N33) -> 0.069698968 | H33: 16084994 | I33: =H33/(D33+F33+J33+L33+N33) -> 0.21799946 | J33: 8040021 | K33: =J33/(D33+F33+H33+J33+L33+N33) -> 0.089463237 | L33: 21389589 | M33: =L33/(D33+F33+H33+J33+L33+N33) -> 0.23800707 | N33: 3027035 | O33: =N33/(D33+F33+H33+J33+L33+N33) -> 0.033682542 | P33: =SUM(D33:N33) -> 89869553
A34: 2016 | B34: Vente.5 | C34: PMUR | D34: 12690387 | E34: =D34/(D34+H34+J34+L34+N34) -> 0.4101798 | F34: 1701929 | G34: =F34/(D34+F34+H34+J34+L34+N34) -> 0.052141594 | H34: 4185934 | I34: =H34/(D34+F34+J34+L34+N34) -> 0.14710927 | J34: 3749776 | K34: =J34/(D34+F34+H34+J34+L34+N34) -> 0.114881 | L34: 8750460 | M34: =L34/(D34+F34+H34+J34+L34+N34) -> 0.26808576 | N34: 1562039 | O34: =N34/(D34+F34+H34+J34+L34+N34) -> 0.047855817 | P34: =SUM(D34:N34) -> 32640526
A35: 2016 | B35: Vente.6 | C35: Total | D35: =SUM(D30:D34) -> 151811334 | E35: =D35/(D35+H35+J35+L35+N35) -> 0.4247236 | F35: =SUM(F30:F34) -> 40903466 | G35: =F35/(D35+F35+H35+J35+L35+N35) -> 0.10268505 | H35: =SUM(H30:H34) -> 77581335 | I35: =H35/(D35+F35+J35+L35+N35) -> 0.24186895 | J35: =SUM(J30:J34) -> 36324696 | K35: =J35/(D35+F35+H35+J35+L35+N35) -> 0.091190394 | L35: =SUM(L30:L34) -> 76573887 | M35: =L35/(D35+F35+H35+J35+L35+N35) -> 0.19223294 | N35: =SUM(N30:N34) -> 15144342 | O35: =N35/(D35+F35+H35+J35+L35+N35) -> 0.038018722 | P35: =SUM(P30:P34) -> 3.9833907e+08 | R35: =Total!S29*1000000 -> 598739168
A36: 2016 | B36: Vente.7 | C36: Point de vente | D36: 962 | E36: =D36/(D36+H36+J36+L36+N36) -> 0.4184428 | F36: 301 | G36: =F36/(D36+F36+H36+J36+L36+N36) -> 0.11576923 | H36: 502 | I36: =H36/(D36+F36+J36+L36+N36) -> 0.2392755 | J36: 255 | K36: =J36/(D36+F36+H36+J36+L36+N36) -> 0.098076923 | L36: 429 | M36: =L36/(D36+F36+H36+J36+L36+N36) -> 0.165 | N36: 151 | O36: =N36/(D36+F36+H36+J36+L36+N36) -> 0.058076923 | P36: =SUM(D36:N36) -> 2601.0366
A37: 2016 | B37: Vente.8 | C37: Population | D37: 773407 | E37: =D37/(D37+H37+J37+L37+N37) -> 0.41925259 | F37: 307461 | G37: =F37/(D37+F37+H37+J37+L37+N37) -> 0.14285967 | H37: 335696 | I37: =H37/(D37+F37+J37+L37+N37) -> 0.18480446 | J37: 178107 | K37: =J37/(D37+F37+H37+J37+L37+N37) -> 0.082756208 | L37: 484736 | M37: =L37/(D37+F37+H37+J37+L37+N37) -> 0.22522929 | N37: 72782 | O37: =N37/(D37+F37+H37+J37+L37+N37) -> 0.033817662 | P37: =SUM(D37:N37) -> 2152190.1
A38: 2017 | B38: Répartition | C38: Répartiton | D38: 40437100 | E38: =D38/(D38+H38+J38+L38+N38) -> 0.3352218 | F38: 17156388 | G38: =F38/(D38+F38+H38+J38+L38+N38) -> 0.12451629 | H38: 27088102 | I38: =H38/(D38+F38+J38+L38+N38) -> 0.24470675 | J38: 14360550 | K38: =J38/(D38+F38+H38+J38+L38+N38) -> 0.10422488 | L38: 32102825 | M38: =L38/(D38+F38+H38+J38+L38+N38) -> 0.23299338 | N38: 6639316 | O38: =N38/(D38+F38+H38+J38+L38+N38) -> 0.048186309 | P38: =SUM(D38:N38)+Q38 -> 149148782 | Q38: 11364500 | S38: 64569860 | T38: 8750600 | U38: 15835213 | V38: 24953377 | W38: 35440433 | X38: 13225300 | Y38: 2933500 | Z38: 10862094 | AA38: 5308500
A39: 2017 | B39: Vente.1 | C39: Billets Instantanés | D39: 43189455 | E39: =D39/(D39+H39+J39+L39+N39) -> 0.43717502 | F39: 11547933 | G39: =F39/(D39+F39+H39+J39+L39+N39) -> 0.10465765 | H39: 23123106 | I39: =H39/(D39+F39+J39+L39+N39) -> 0.26512165 | J39: 11307647 | K39: =J39/(D39+F39+H39+J39+L39+N39) -> 0.10247997 | L39: 16591099 | M39: =L39/(D39+F39+H39+J39+L39+N39) -> 0.15036332 | N39: 4580831 | O39: =N39/(D39+F39+H39+J39+L39+N39) -> 0.041515571 | P39: =SUM(D39:N39) -> 1.1034007e+08
A40: 2017 | B40: Vente.2 | C40: Jeux de tirages | D40: 57395367 | E40: =D40/(D40+H40+J40+L40+N40) -> 0.42950607 | F40: 19735210 | G40: =F40/(D40+F40+H40+J40+L40+N40) -> 0.12868022 | H40: 30927732 | I40: =H40/(D40+F40+J40+L40+N40) -> 0.25259794 | J40: 11852157 | K40: =J40/(D40+F40+H40+J40+L40+N40) -> 0.077280058 | L40: 27987042 | M40: =L40/(D40+F40+H40+J40+L40+N40) -> 0.18248495 | N40: 5468798 | O40: =N40/(D40+F40+H40+J40+L40+N40) -> 0.035658406 | P40: =SUM(D40:N40) -> 1.5336631e+08
...

Sheet par habitant
A1: Dépense par habitant pour la Loro
A2: Canton | B2: 2013 | C2: 2014 | D2: 2015 | E2: 2016 | F2: 2017 | G2: 2018 | H2: 2019 | I2: 2020 | J2: 2021 | K2: 2022 | L2: 2023 | M2: 2024
A3: Vaud | B3: ='Détail'!D8/'Détail'!D10 -> 198.03506 | C3: ='Détail'!D$17/'Détail'!D$19 -> 199.10221 | D3: ='Détail'!D$26/'Détail'!D$28 -> 189.5157 | E3: ='Détail'!D$35/'Détail'!D$37 -> 196.28906 | F3: ='Détail'!D$44/'Détail'!D$46 -> 189.26975 | G3: ='Détail'!D$53/'Détail'!D$55 -> 187.18778 | H3: ='Détail'!D$62/'Détail'!D$64 -> 196.54186 | I3: ='Détail'!D$71/'Détail'!D$73 -> 177.12257 | J3: ='Détail'!D$80/'Détail'!D$82 -> 185.33034 | K3: ='Détail'!D$89/'Détail'!D$91 -> 201.37115 | L3: ='Détail'!D$98/'Détail'!D$100 -> 191.15425 | M3: ='Détail'!D$107/'Détail'!D$109 -> 193.80635
A4: Fribourg | B4: ='Détail'!F8/'Détail'!F10 -> 124.81936 | C4: ='Détail'!F$17/'Détail'!F$19 -> 129.90475 | D4: ='Détail'!F$26/'Détail'!F$28 -> 124.8328 | E4: ='Détail'!F$35/'Détail'!F$37 -> 133.03627 | F4: ='Détail'!F$44/'Détail'!F$46 -> 127.64739 | G4: ='Détail'!F$53/'Détail'!F$55 -> 128.36699 | H4: ='Détail'!F$62/'Détail'!F$64 -> 134.47671 | I4: ='Détail'!F$71/'Détail'!F$73 -> 128.78286 | J4: ='Détail'!F$80/'Détail'!F$82 -> 134.54562 | K4: ='Détail'!F$89/'Détail'!F$91 -> 143.80264 | L4: ='Détail'!F$98/'Détail'!F$100 -> 136.97401 | M4: ='Détail'!F$107/'Détail'!F$109 -> 144.19995
A5: Valais | B5: ='Détail'!H8/'Détail'!H10 -> 232.15384 | C5: ='Détail'!H$17/'Détail'!H$19 -> 230.1104 | D5: ='Détail'!H$26/'Détail'!H$28 -> 218.33792 | E5: ='Détail'!H$35/'Détail'!H$37 -> 231.10593 | F5: ='Détail'!H$44/'Détail'!H$46 -> 216.88101 | G5: ='Détail'!H$53/'Détail'!H$55 -> 215.91945 | H5: ='Détail'!H$62/'Détail'!H$64 -> 221.44568 | I5: ='Détail'!H$71/'Détail'!H$73 -> 202.25615 | J5: ='Détail'!H$80/'Détail'!H$82 -> 209.29672 | K5: ='Détail'!H$89/'Détail'!H$91 -> 226.31543 | L5: ='Détail'!H$98/'Détail'!H$100 -> 213.83614 | M5: ='Détail'!H$107/'Détail'!H$109 -> 217.16404
A6: Neuchâtel | B6: ='Détail'!J8/'Détail'!J10 -> 207.37901 | C6: ='Détail'!J17/'Détail'!J$19 -> 203.51213 | D6: ='Détail'!J$26/'Détail'!J$28 -> 196.72686 | E6: ='Détail'!J$35/'Détail'!J$37 -> 203.94873 | F6: ='Détail'!J$44/'Détail'!J$46 -> 196.30338 | G6: ='Détail'!J$53/'Détail'!J$55 -> 198.33063 | H6: ='Détail'!J$62/'Détail'!J$64 -> 206.7956 | I6: ='Détail'!J$71/'Détail'!J$73 -> 193.3285 | J6: ='Détail'!J$80/'Détail'!J$82 -> 201.79386 | K6: ='Détail'!J$89/'Détail'!J$91 -> 220.65849 | L6: ='Détail'!J$98/'Détail'!J$100 -> 206.06733 | M6: ='Détail'!J$107/'Détail'!J$109 -> 207.0791
A7: Genève | B7: ='Détail'!L8/'Détail'!L10 -> 152.14183 | C7: ='Détail'!L$17/'Détail'!L$19 -> 157.76273 | D7: ='Détail'!L$26/'Détail'!L$28 -> 152.60579 | E7: ='Détail'!L$35/'Détail'!L$37 -> 157.97029 | F7: ='Détail'!L$44/'Détail'!L$46 -> 153.93111 | G7: ='Détail'!L$53/'Détail'!L$55 -> 153.78482 | H7: ='Détail'!L$62/'Détail'!L$64 -> 161.78239 | I7: ='Détail'!L$71/'Détail'!L$73 -> 144.87653 | J7: ='Détail'!L$80/'Détail'!L$82 -> 157.91131 | K7: ='Détail'!L$89/'Détail'!L$91 -> 174.00792 | L7: ='Détail'!L$98/'Détail'!L$100 -> 173.15825 | M7: ='Détail'!L$107/'Détail'!L$109 -> 178.52443
A8: Jura | B8: ='Détail'!N8/'Détail'!N10 -> 205.63405 | C8: ='Détail'!N$17/'Détail'!N$19 -> 203.10041 | D8: ='Détail'!N$26/'Détail'!N$28 -> 199.86364 | E8: ='Détail'!N$35/'Détail'!N$37 -> 208.07812 | F8: ='Détail'!N44/'Détail'!N46 -> 193.66754 | G8: ='Détail'!N$53/'Détail'!N$55 -> 189.21213 | H8: ='Détail'!N$62/'Détail'!N$64 -> 198.67262 | I8: ='Détail'!N$71/'Détail'!N$73 -> 179.44307 | J8: ='Détail'!N$80/'Détail'!N$82 -> 187.28961 | K8: ='Détail'!N$89/'Détail'!N$91 -> 201.59854 | L8: ='Détail'!N$98/'Détail'!N$100 -> 194.22167 | M8: ='Détail'!N$107/'Détail'!N$109 -> 202.04633
A9: Romandie | B9: ='Détail'!P8/'Détail'!P10 -> 183.71613 | C9: ='Détail'!P17/'Détail'!P19 -> 185.33451 | D9: ='Détail'!P26/'Détail'!P$28 -> 177.4361 | E9: ='Détail'!P35/'Détail'!P37 -> 185.08545 | F9: ='Détail'!P44/'Détail'!P46 -> 177.52143 | G9: ='Détail'!P53/'Détail'!P55 -> 176.65413 | H9: ='Détail'!P62/'Détail'!P64 -> 184.51088 | I9: ='Détail'!P71/'Détail'!P73 -> 168.09726 | J9: ='Détail'!P80/'Détail'!P82 -> 176.85652 | K9: ='Détail'!P89/'Détail'!P91 -> 192.23286 | L9: ='Détail'!P98/'Détail'!P100 -> 183.97808 | M9: ='Détail'!P107/'Détail'!P109 -> 188.04336
A12: Dépense par habitant pour la Loterie electronique (Tactilo) - https://www.loterie-electronique.ch/fr/faq#t20n42 | H12: https://www.vd.ch/typo3temp/assets/pdfs/tactilo-les-cantons-romands-rejettent-la-decision-dinterdiction-1168623969.pdf
A13: Canton | B13: 2013 | C13: 2014 | D13: 2015 | E13: 2016 | F13: 2017 | G13: 2018 | H13: 2019 | I13: 2020 | J13: 2021 | K13: 2022 | L13: 2023 | M13: 2024
A14: Vaud | B14: ='Détail'!$D$6/'Détail'!$D$10 -> 48.406499 | C14: ='Détail'!$D$15/'Détail'!$D$19 -> 46.647675 | D14: ='Détail'!$D$24/'Détail'!$D$28 -> 45.428042 | E14: ='Détail'!$D$33/'Détail'!$D$37 -> 45.337187 | F14: ='Détail'!$D$42/'Détail'!$D$46 -> 41.965447 | G14: ='Détail'!$D$51/'Détail'!$D$55 -> 41.6145 | H14: ='Détail'!$D$60/'Détail'!$D$64 -> 38.138365 | I14: ='Détail'!$D$69/'Détail'!$D$73 -> 21.067628 | J14: ='Détail'!$D$78/'Détail'!$D$82 -> 17.633817 | K14: ='Détail'!$D$87/'Détail'!$D$91 -> 31.394681 | L14: ='Détail'!$D$96/'Détail'!$D$100 -> 29.55448 | M14: ='Détail'!$D$105/'Détail'!$D$109 -> 26.711723
A15: Fribourg | B15: ='Détail'!$F$6/'Détail'!$F$10 -> 19.660512 | C15: ='Détail'!$F$15/'Détail'!$F$19 -> 20.52013 | D15: ='Détail'!$F$24/'Détail'!$F$28 -> 19.803096 | E15: ='Détail'!$F$33/'Détail'!$F$37 -> 20.372714 | F15: ='Détail'!$F$42/'Détail'!$F$46 -> 20.071658 | G15: ='Détail'!$F$51/'Détail'!$F$55 -> 19.472092 | H15: ='Détail'!$F$60/'Détail'!$F$64 -> 18.390883 | I15: ='Détail'!$F$69/'Détail'!$F$73 -> 10.506136 | J15: ='Détail'!$F$78/'Détail'!$F$82 -> 8.7385559 | K15: ='Détail'!$F$87/'Détail'!$F$91 -> 14.736141 | L15: ='Détail'!$F$96/'Détail'!$F$100 -> 13.849605 | M15: ='Détail'!$F$105/'Détail'!$F$109 -> 12.121814
A16: Valais | B16: ='Détail'!$H$6/'Détail'!$H$10 -> 54.105336 | C16: ='Détail'!$H$15/'Détail'!$H$19 -> 49.348777 | D16: ='Détail'!$H$24/'Détail'!$H$28 -> 47.515036 | E16: ='Détail'!$H$33/'Détail'!$H$37 -> 47.915358 | F16: ='Détail'!$H$42/'Détail'!$H$46 -> 43.167476 | G16: ='Détail'!$H$51/'Détail'!$H$55 -> 42.329233 | H16: ='Détail'!$H$60/'Détail'!$H$64 -> 36.75548 | I16: ='Détail'!$H$69/'Détail'!$H$73 -> 20.343489 | J16: ='Détail'!$H$78/'Détail'!$H$82 -> 15.463517 | K16: ='Détail'!$H$87/'Détail'!$H$91 -> 27.707522 | L16: ='Détail'!$H$96/'Détail'!$H$100 -> 24.595034 | M16: ='Détail'!$H$105/'Détail'!$H$109 -> 22.08868
A17: Neuchâtel | B17: ='Détail'!$J$6/'Détail'!$J$10 -> 49.898576 | C17: ='Détail'!$J$15/'Détail'!$J$19 -> 48.029773 | D17: ='Détail'!$J$24/'Détail'!$J$28 -> 46.679101 | E17: ='Détail'!$J$33/'Détail'!$J$37 -> 45.141522 | F17: ='Détail'!$J$42/'Détail'!$J$46 -> 43.702123 | G17: ='Détail'!$J$51/'Détail'!$J$55 -> 42.520678 | H17: ='Détail'!$J$60/'Détail'!$J$64 -> 38.493882 | I17: ='Détail'!$J$69/'Détail'!$J$73 -> 22.53161 | J17: ='Détail'!$J$78/'Détail'!$J$82 -> 19.170768 | K17: ='Détail'!$J$87/'Détail'!$J$91 -> 33.160576 | L17: ='Détail'!$J$96/'Détail'!$J$100 -> 30.966495 | M17: ='Détail'!$J$105/'Détail'!$J$109 -> 27.948208
A18: Genève | B18: ='Détail'!$L$6/'Détail'!$L$10 -> 49.617634 | C18: ='Détail'!$L$15/'Détail'!$L$19 -> 45.821762 | D18: ='Détail'!$L$24/'Détail'!$L$28 -> 44.459956 | E18: ='Détail'!$L$33/'Détail'!$L$37 -> 44.126265 | F18: ='Détail'!$L$42/'Détail'!$L$46 -> 41.433162 | G18: ='Détail'!$L$51/'Détail'!$L$55 -> 39.601774 | H18: ='Détail'!$L$60/'Détail'!$L$64 -> 35.864555 | I18: ='Détail'!$L$69/'Détail'!$L$73 -> 19.798906 | J18: ='Détail'!$L$78/'Détail'!$L$82 -> 16.940406 | K18: ='Détail'!$L$87/'Détail'!$L$91 -> 28.148484 | L18: ='Détail'!$L$96/'Détail'!$L$100 -> 27.704606 | M18: ='Détail'!$L$105/'Détail'!$L$109 -> 25.435947
A19: Jura | B19: ='Détail'!N$6/'Détail'!$N$10 -> 43.814313 | C19: ='Détail'!$N$15/'Détail'!$N$19 -> 41.904862 | D19: ='Détail'!$N$24/'Détail'!$N$28 -> 41.912733 | E19: ='Détail'!$N$33/'Détail'!$N$37 -> 41.590434 | F19: ='Détail'!$N$42/'Détail'!$N$46 -> 36.318878 | G19: ='Détail'!$N$51/'Détail'!$N$55 -> 33.468236 | H19: ='Détail'!$N$60/'Détail'!$N$64 -> 32.649505 | I19: ='Détail'!$N$69/'Détail'!$N$73 -> 16.573263 | J19: ='Détail'!$N$78/'Détail'!$N$82 -> 13.609139 | K19: ='Détail'!$N$87/'Détail'!$N$91 -> 25.967208 | L19: ='Détail'!$N$96/'Détail'!$N$100 -> 24.954891 | M19: ='Détail'!N$105/'Détail'!$N$109 -> 23.028519
A20: Romandie | B20: ='Détail'!P$6/'Détail'!$P$10 -> 45.465252 | C20: ='Détail'!$P$15/'Détail'!$P$19 -> 43.120659 | D20: ='Détail'!$P$24/'Détail'!$P$28 -> 41.860451 | E20: ='Détail'!$P$33/'Détail'!$P$37 -> 41.757257 | F20: ='Détail'!$P$42/'Détail'!$P$46 -> 38.849107 | G20: ='Détail'!$P$51/'Détail'!$P$55 -> 37.896638 | H20: ='Détail'!$P$60/'Détail'!$P$64 -> 34.410088 | I20: ='Détail'!$P$69/'Détail'!$P$73 -> 19.109201 | J20: ='Détail'!$P$78/'Détail'!$P$82 -> 15.838856 | K20: ='Détail'!$P$87/'Détail'!$P$91 -> 27.625049 | L20: ='Détail'!$P$96/'Détail'!$P$100 -> 26.027103 | M20: ='Détail'!$P$105/'Détail'!$P$109 -> 23.537519
A23: Dépense par habitant pour les paris sportifs
A24: Canton | B24: 2013 | C24: 2014 | D24: 2015 | E24: 2016 | F24: 2017 | G24: 2018 | H24: 2019 | I24: 2020 | J24: 2021 | K24: 2022 | L24: 2023 | M24: 2024
A25: Vaud | B25: ='Détail'!$D$5/'Détail'!$D$10 -> 2.3088257 | C25: ='Détail'!$D$14/'Détail'!$D$19 -> 2.6856679 | D25: ='Détail'!$D$23/'Détail'!$D$28 -> 2.584572 | E25: ='Détail'!$D$32/'Détail'!$D$37 -> 3.0887476 | F25: ='Détail'!$D$41/'Détail'!$D$46 -> 3.2121385 | G25: ='Détail'!$D$50/'Détail'!$D$55 -> 5.6382291 | H25: ='Détail'!$D$59/'Détail'!$D$64 -> 10.122565 | I25: ='Détail'!$D$68/'Détail'!$D$73 -> 11.95253 | J25: ='Détail'!$D$77/'Détail'!$D$82 -> 18.191244 | K25: ='Détail'!$D$86/'Détail'!$D$91 -> 19.040428 | L25: ='Détail'!$D$95/'Détail'!$D$100 -> 19.696683 | M25: ='Détail'!$D$104/'Détail'!$D$109 -> 24.587072
A26: Fribourg | B26: ='Détail'!$F$5/'Détail'!$F$10 -> 1.6183153 | C26: ='Détail'!$F$14/'Détail'!$F$19 -> 1.7566208 | D26: ='Détail'!$F$23/'Détail'!$F$28 -> 2.4891373 | E26: ='Détail'!$F$32/'Détail'!$F$37 -> 2.696664 | F26: ='Détail'!$F$41/'Détail'!$F$46 -> 2.3146669 | G26: ='Détail'!$F$50/'Détail'!$F$55 -> 4.1099615 | H26: ='Détail'!$F$59/'Détail'!$F$64 -> 6.127936 | I26: ='Détail'!$F$68/'Détail'!$F$73 -> 7.9285916 | J26: ='Détail'!$F$77/'Détail'!$F$82 -> 11.009072 | K26: ='Détail'!$F$86/'Détail'!$F$91 -> 12.154277 | L26: ='Détail'!$F$95/'Détail'!$F$100 -> 12.495801 | M26: ='Détail'!$F$104/'Détail'!$F$109 -> 15.481977
A27: Valais | B27: ='Détail'!$H$5/'Détail'!$H$10 -> 2.818986 | C27: ='Détail'!$H$14/'Détail'!$H$19 -> 3.1568143 | D27: ='Détail'!$H$23/'Détail'!$H$28 -> 3.1882519 | E27: ='Détail'!$H$32/'Détail'!$H$37 -> 3.7617011 | F27: ='Détail'!$H$41/'Détail'!$H$46 -> 3.2146585 | G27: ='Détail'!$H$50/'Détail'!$H$55 -> 6.1407971 | H27: ='Détail'!$H$59/'Détail'!$H$64 -> 7.8743702 | I27: ='Détail'!$H$68/'Détail'!$H$73 -> 11.487311 | J27: ='Détail'!$H$77/'Détail'!$H$82 -> 16.678232 | K27: ='Détail'!$H$86/'Détail'!$H$91 -> 16.669153 | L27: ='Détail'!$H$95/'Détail'!$H$100 -> 15.381637 | M27: ='Détail'!$H$104/'Détail'!$H$109 -> 19.557005
A28: Neuchâtel | B28: ='Détail'!$J$5/'Détail'!$J$10 -> 2.4289561 | C28: ='Détail'!$J$14/'Détail'!$J$19 -> 3.3119863 | D28: ='Détail'!$J$23/'Détail'!$J$28 -> 2.9982687 | E28: ='Détail'!$J$32/'Détail'!$J$37 -> 3.2461386 | F28: ='Détail'!$J$41/'Détail'!$J$46 -> 3.5932451 | G28: ='Détail'!$J$50/'Détail'!$J$55 -> 5.1366962 | H28: ='Détail'!$J$59/'Détail'!$J$64 -> 8.0583263 | I28: ='Détail'!$J$68/'Détail'!$J$73 -> 10.89619 | J28: ='Détail'!$J$77/'Détail'!$J$82 -> 16.415324 | K28: ='Détail'!$J$86/'Détail'!$J$91 -> 19.343846 | L28: ='Détail'!$J$95/'Détail'!$J$100 -> 16.545271 | M28: ='Détail'!$J$104/'Détail'!$J$109 -> 21.866494
A29: Genève | B29: ='Détail'!$L$5/'Détail'!$L$10 -> 1.8481713 | C29: ='Détail'!$L$14/'Détail'!$L$19 -> 3.141264 | D29: ='Détail'!$L$23/'Détail'!$L$28 -> 3.4249861 | E29: ='Détail'!$L$32/'Détail'!$L$37 -> 3.9552127 | F29: ='Détail'!$L$41/'Détail'!$L$46 -> 3.8373645 | G29: ='Détail'!$L$50/'Détail'!$L$55 -> 7.4137595 | H29: ='Détail'!$L$59/'Détail'!$L$64 -> 10.319933 | I29: ='Détail'!$L$68/'Détail'!$L$73 -> 13.870364 | J29: ='Détail'!$L$77/'Détail'!$L$82 -> 20.717239 | K29: ='Détail'!$L$86/'Détail'!$L$91 -> 22.743358 | L29: ='Détail'!$L$95/'Détail'!$L$100 -> 27.34166 | M29: ='Détail'!$L$104/'Détail'!$L$109 -> 31.225823
A30: Jura | B30: ='Détail'!N$5/'Détail'!$N$10 -> 1.5184658 | C30: ='Détail'!$N$14/'Détail'!$N$19 -> 1.5174524 | D30: ='Détail'!$N$23/'Détail'!$N$28 -> 1.9240436 | E30: ='Détail'!$N$32/'Détail'!$N$37 -> 2.1809926 | F30: ='Détail'!$N$41/'Détail'!$N$46 -> 2.2295752 | G30: ='Détail'!$N$50/'Détail'!$N$55 -> 4.3851822 | H30: ='Détail'!$N$59/'Détail'!$N$64 -> 6.3431401 | I30: ='Détail'!$N$68/'Détail'!$N$73 -> 8.6566509 | J30: ='Détail'!$N$77/'Détail'!$N$82 -> 13.034311 | K30: ='Détail'!$N$86/'Détail'!$N$91 -> 11.81135 | L30: ='Détail'!$N$95/'Détail'!$N$100 -> 13.199458 | M30: ='Détail'!N$104/'Détail'!$N$109 -> 17.419703
A31: Romandie | B31: ='Détail'!P$5/'Détail'!$P$10 -> 2.1699656 | C31: ='Détail'!$P$14/'Détail'!$P$19 -> 2.7421389 | D31: ='Détail'!$P$23/'Détail'!$P$28 -> 2.8661812 | E31: ='Détail'!$P$32/'Détail'!$P$37 -> 3.3151803 | F31: ='Détail'!$P$41/'Détail'!$P$46 -> 3.2227891 | G31: ='Détail'!$P$50/'Détail'!$P$55 -> 5.8150483 | H31: ='Détail'!$P$59/'Détail'!$P$64 -> 8.9512705 | I31: ='Détail'!$P$68/'Détail'!$P$73 -> 11.54037 | J31: ='Détail'!$P$77/'Détail'!$P$82 -> 17.176171 | K31: ='Détail'!$P$86/'Détail'!$P$91 -> 18.289002 | L31: ='Détail'!$P$95/'Détail'!$P$100 -> 19.234832 | M31: ='Détail'!$P$104/'Détail'!$P$109 -> 23.519528

Sheet Subv_TdR
B1: Canton | D1: 2013 | E1: 2014 | F1: 2015 | G1: 2016 | H1: 2017 | I1: 2018 | J1: 2019 | K1: 2020 | L1: 2021 | M1: 2022 | N1: 2023 | O1: 2024 | P1: 2025
A2: Tour de Romandie | D2: =SUM(D3:D90) -> 915100.15 | E2: =SUM(E3:E90) -> 933790.43 | F2: =SUM(F3:F90) -> 936964.6 | G2: =SUM(G3:G90) -> 982353 | H2: =SUM(H3:H90) -> 975478 | I2: =SUM(I3:I90) -> 997738 | J2: =SUM(J3:J90) -> 974046 | K2: =SUM(K3:K90) -> 760118 | ... P2: =SUM(P3:P90) -> 0 | Q2: Budget total 2026
A3: Administration communale de Chalais | B3: Valais | C3: Féminin | O3: 6149
A4: Administration communale de Chambéry | B4: Valais | I4: 8300
A5: Administration communale de Saillon | B5: Valais | O5: 1692
A6: Assoc. Courses Cyclistes Lausanne | B6: Vaud | C6: Féminin | M6: 6000 | O6: 6000
A7: Assoc. Courses Cyclistes Lausanne | B7: Vaud | C7: Masculin | M7: 6000
A8: Assoc. Organisation étape Aigle MY Tour de Romandie | L8: 2713
A9: Assoc. pour lorganisation de létape Aigle-Martigny du Tour de Romandie 2021 | L9: 5000
A10: Assoc. pour l’organisation locale d’étapes du tour de Romandie à Bulle | B10: Fribourg | H10: 1000
A11: Assoc. Région Neuchâtel Littoral | B11: Neuchâtel | C11: Féminin | O11: 10000
A12: Assoc. Région Neuchâtel Littoral | B12: Neuchâtel | C12: Masculin | O12: 40000
A13: Assoc. Sport Evènement | B13: Valais | K13: 8118
A14: Assoc. Sport Événement, Vionnaz Torgon | B14: Valais | C14: Féminin | N14: 5053
A15: Assoc. Sport Tourisme Culture Vallorbe-Vallée de Joux | N15: 6000
A16: Assoc. Tour de Romandie Les Diablerets | E16: 1600
A17: Association Tour de Romandie | B17: Neuchatel | E17: 20000
A18: Broye Sport Events | B18: Vaud | C18: Masculin | O18: 6000
A19: Cimes Cycle La Chaux-de-Fonds | G19: 20000
A20: Comité dorganisation Fribourg | M20: 2000
A21: Commune d’Aigle | H21: 7000
A22: Commune dOron | B22: Vaud | C22: Masculin | O22: 7500
A23: Commune dYverdon-les-Bains | B23: Vaud | C23: Féminin | N23: 5500
A24: Commune dYverdon-les-Bains | B24: Vaud | C24: Masculin | I24: 5000
A25: Commune de Château-dOEx | B25: Vaud | C25: Masculin | O25: 2500
A26: Commune de Conthey | B26: Valais | G26: 1350
A27: Commune de Crissier | B27: Vaud | C27: Masculin | N27: 8000
A28: Commune de la Béroche | M28: 15000
A29: Commune de Lausanne | H29: 5500
A30: Commune de Leysin | B30: Vaud | C30: Masculin | H30: 5000 | O30: 7000
A31: Commune de Montreux | E31: 5000
A32: Commune de Morges | B32: Vaud | C32: Féminin | O32: 8000
A33: Commune de Moudon | G33: 7000
A34: Commune de Nyon | B34: Vaud | C34: Féminin | N34: 8000
A35: Commune de Port-Valais | B35: Valais | C35: Masculin | N35: 6589
A36: Commune de Vufflens-la-Ville | B36: Vaud | C36: Masculin | N36: 8000
A37: Cyclophile Romontois | B37: Fribourg | J37: 1000 | M37: 1000
A38: Cyclophile Sédunois, Sion | B38: Valais | G38: 4003 | I38: 4078 | M38: 2361 | N38: 4287
A39: Delémont | B39: Jura | I39: 25000
A40: Etape Ascona Sion | E40: 6190
...

Sheet Subv_Cinéforom
B1: Canton | D1: 2013 | E1: 2014 | F1: 2015 | G1: 2016 | H1: 2017 | I1: 2018 | J1: 2019 | K1: 2020 | L1: 2021 | M1: 2022 | N1: 2023 | O1: 2024 | P1: 2025
A2: Fond. Cinéforom | D2: =SUM(D3:D33) -> 2920000 | E2: =SUM(E3:E33) -> 3015000 | F2: =SUM(F3:F33) -> 3210000 | G2: =SUM(G3:G33) -> 3010000 | H2: =SUM(H3:H33) -> 2660000 | I2: =SUM(I3:I33) -> 2660000 | J2: =SUM(J3:J33) -> 2720000 | K2: =SUM(K3:K33) -> 2660000 | ... P2: =SUM(P3:P33) -> 2800335
A3: Fond. Cinéforom | B3: Conférence des Présidents des Organes de Répartition | D3: 1600000 | E3: 1700000 | F3: 1700000 | G3: 1700000 | H3: 1700000 | I3: 1700000 | J3: 1700000 | K3: 1700000 | L3: 1700000 | M3: 1700000 | N3: 1700000 | O3: 1700000 | P3: 1700000
A4: Fond. Cinéforom | B4: Fribourg | L4: 185000 | M4: 185200 | N4: 185200 | O4: 185200 | P4: 234600
A5: Fond. Cinéforom | B5: Genève | C5: Soutien à la diversité de la production audiovisuelle indépendante | D5: 350000 | E5: 350000 | F5: 550000 | G5: 350000 | M5: 85735 | N5: 85735 | O5: 85735
A6: Fond. Cinéforom | B6: Neuchâtel | L6: 156800 | O6: 50000
A7: Fond. Cinéforom | B7: Jura | O7: 25000
A8: Fond. Cinéforom | B8: Vaud | D8: 700000 | E8: 700000 | F8: 700000 | G8: 700000 | H8: 700000 | I8: 700000 | J8: 700000 | K8: 700000 | L8: 700000 | M8: 700000 | N8: 700000 | O8: 700000 | P8: 700000
A9: Fond. Cinéforom | B9: Fribourg | C9: Soutien à la diversité de la production audiovisuelle indépendante | J9: 80000 | K9: 80000 | L9: 80000 | M9: 80000 | N9: 80000 | O9: 80000 | P9: 80000
A10: Fond. Cinéforom, | B10: Valais | C10: Soutien à la diversité de la production audiovisuelle indépendante | D10: 270000 | E10: 265000 | F10: 260000 | G10: 260000 | H10: 260000 | I10: 260000 | J10: 240000 | K10: 180000 | L10: 130000 | P10: 85735

Sheet Subv_EMS
B1: Canton | D1: 2013 | E1: 2014 | F1: 2015 | G1: 2016 | H1: 2017 | I1: 2018 | J1: 2019 | K1: 2020 | L1: 2021 | M1: 2022 | N1: 2023 | O1: 2024 | P1: 2025
A3: Tertianum La Venise, Monthey | B3: Valais | M3: 16000 | N3: 23000 | O3: 20000 | P3: 26000
A4: Tertianum Les Marronniers, Martigny | B4: Valais | D4: 27300 | E4: 27300 | F4: 26650 | G4: 27300 | H4: 27300 | I4: 27300 | J4: 27300 | K4: 27300 | L4: 27300 | M4: 30000 | N4: 30000 | O4: 31000 | P4: 42000
A5: Tertianum Les Sources, Saxon | B5: Valais | F5: 24050 | G5: 42900 | H5: 44200 | I5: 44200 | J5: 44200 | K5: 44200 | L5: 44200 | M5: 37000 | N5: 39000 | O5: 35000 | P5: 50000
A6: Tertianum Les Tourelles, Martigny | B6: Valais | D6: 23400 | E6: 29250 | F6: 28600 | G6: 29900 | H6: 29900 | I6: 29900 | J6: 29900 | K6: 29900 | L6: 29900 | M6: 29000 | N6: 32000 | O6: 29000 | P6: 38000
A7: EMS Les Vergers, Aproz | B7: Valais | H7: 37700 | I7: 48750 | J7: 48750 | K7: 48750 | L7: 48750

Sheet Subv_musique classique
B1: Canton | D1: 2013 | E1: 2014 | F1: 2015 | G1: 2016 | H1: 2017 | I1: 2018 | J1: 2019 | K1: 2020 | L1: 2021 | M1: 2022 | N1: 2023 | O1: 2024 | P1: 2025
A3: Fond. du Verbier Festival | B3: Valais | D3: 800000 | E3: =775000+150000 -> 925000 | F3: =775000+150000 -> 925000 | G3: =725000 -> 725000 | H3: =775000+150000 -> 925000 | I3: 904000 | J3: 775000 | K3: =775000+150000 -> 925000 | L3: 975000 | M3: =975000+150000 -> 1125000 | N3: =160000+975000 -> 1135000 | O3: 750000 | P3: =775000+150000 -> 925000
A5: Orchestre de Chambre de Genève | B5: Genève | D5: 100000 | E5: 150000 | F5: 150000 | G5: 150000 | H5: 150000 | I5: 150000 | J5: 150000 | K5: 350000 | L5: 350000 | M5: 350000 | N5: =450000+3000 -> 453000 | O5: 400000 | P5: 500000
A6: Orchestre de Chambre de Lausanne | B6: Vaud | D6: 220000 | E6: 220000 | F6: 220000 | G6: 230000 | H6: 220000 | I6: 440000 | J6: 220000 | K6: 226000 | L6: 200000 | M6: 200000 | N6: 220000 | O6: 250000 | P6: 260000
A7: Orchestre de Chambre fribourgeois | B7: Fribourg | D7: 300000 | E7: 320000 | F7: 320000 | G7: 400000 | H7: 400000 | I7: 400000 | J7: 430000 | K7: 400000 | L7: 410000 | M7: 410000 | N7: 410000 | O7: =425000+9100 -> 434100 | P7: 435500
A9: Fond. OSR, Genève | B9: Genève | D9: 500000 | E9: =260000+500000 -> 760000 | F9: =500000 -> 500000 | G9: 300000 | H9: 400000 | I9: 400000 | J9: 400000 | K9: 300000 | L9: =400000 -> 400000 | M9: 450000 | N9: =200000+90000 -> 290000 | O9: 350000 | P9: 317600
A10: Assoc. vaudoise des Amis de l’Orchestre de la Suisse Romande - AVAOSR | E10: 105000 | F10: 105000 | G10: 95000 | H10: 90000 | J10: 90000 | K10: 95000 | M10: 90000 | N10: 90000 | P10: 100000
A11: Fond. de l'Orchestre de la Suisse Romande | O11: 100000 | P11: 120000

Sheet Subv_Festival Cinéma
B1: Canton | D1: 2013 | E1: 2014 | F1: 2015 | G1: 2016 | H1: 2017 | I1: 2018 | J1: 2019 | K1: 2020 | L1: 2021 | M1: 2022 | N1: 2023 | O1: 2024 | P1: 2025
A2: FIFF | D2: 570000 | E2: 570000 | F2: 570000 | G2: 570000 | H2: 570000 | I2: 580000 | J2: 570000 | K2: 580000 | L2: =580000+250000 -> 830000 | M2: =580000 -> 580000 | N2: =215000+580000 -> 795000 | O2: =580000+75000 -> 655000 | P2: =660000+175000 -> 835000
A3: NIFFF | D3: 190000 | E3: 200000 | F3: 210000 | G3: 230000 | H3: 250000 | I3: 250000 | J3: 280000 | K3: 300000 | L3: 283000 | M3: 350000 | N3: 350000 | O3: 350000 | P3: 375000
A4: GIFF | D4: 350000 | E4: 350000 | F4: 350000 | G4: 350000 | H4: 390000 | I4: 350000 | J4: 300000 | K4: 300000 | L4: 300000 | M4: 300000 | N4: 300000 | O4: 300000 | P4: 380000
A5: FIFDH | D5: 300000 | E5: 300000 | F5: 300000 | G5: 300000 | H5: 300000 | I5: 300000 | J5: 300000 | K5: 300000 | L5: 300000 | M5: 400000 | N5: 300000 | O5: =350000 -> 350000 | P5: 400000

Sheet Subv_divers
B1: Canton | D1: 2013 | E1: 2014 | F1: 2015 | G1: 2016 | H1: 2017 | I1: 2018 | J1: 2019 | K1: 2020 | L1: 2021 | M1: 2022 | N1: 2023 | O1: 2024 | P1: 2025
A3: Fond. Salle de concerts et Congrès Sion | B3: Valais | H3: 3000000 | P3: 240000
A4: Switzerland for UNHCR | B4: Genève | O4: 1500000
A5: Fond. pour la Rénovation de la Caserne de la Garde Suisse Pontificale au Vatican | B5: Fribourg | L5: 50000
A6: Transports publics fribourgeois Holding (TPF) SA | B6: Fribourg | L6: 50000
A8: Fond. du Stade de Genève | G8: 600000 | K8: 100000 | L8: 384000
A9: Commune de Sion - Mise en conformité Stade de Tourbillon | H9: 150000
A10: Commune d’Yverdon-les-Bains Stade municipal | N10: 521398 | P10: 140000
A12: Jura Tourisme | B12: Jura | D12: 335000 | E12: 320000 | F12: 345000 | G12: 300000 | H12: 300000 | I12: 300000 | J12: 330000 | K12: 330000 | L12: =300000+120000 -> 420000 | M12: 300000 | N12: 300000 | O12: 300000 | P12: 320000
A13: Valais/Wallis Promotion | B13: Valais | E13: 500000 | F13: 500000 | G13: 500000 | H13: 500000 | I13: 500000 | J13: 540000 | K13: 500000 | L13: 500000 | M13: 500000 | N13: 500000 | O13: 500000 | P13: 500000
A14: Vaud Promotion | B14: Vaud | D14: 1000000 | E14: 1000000 | F14: 1000000 | G14: 1000000 | H14: 1000000 | I14: 1000000 | J14: 1000000 | K14: 1000000 | L14: 1000000 | M14: 1000000 | N14: 1000000 | O14: 1000000 | P14: 1000000
A17: Ski-Club Gendarmerie Vaudoise | B17: Vaud | D17: 16600
A18: Vélo-Club de la Police cant. vaudoise | B18: Vaud | D18: 500 | E18: 500 | F18: 500 | G18: 500
A19: Commission sportive suisse de police - Champ. dEurope de ski de la police aux Diablerets | B19: Vaud | D19: 6000
A20: Police Cantonale Vaudoise Journée sportive de la Police cantonale au Centre sportif de Vallorbe | B20: Vaud | D20: 1000 | E20: 1000 | F20: 1000 | I20: 1000 | N20: 1000 | P20: 1000
A21: Comm. sportive suisse de Police Soutien complémentaire pour lorg. du Champ. dEurope de ski | B21: Vaud | D21: 4000
A22: Fanfare de la Police cantonale valaisanne | B22: Valais | E22: 4000 | N22: 10000
A23: Championnat suisse de judo police | B23: Vaud | F23: 1000 | H23: 1000
A24: Match Suisse-Finlande qualificatif pour les Champ. d’Europe football police | B24: Vaud | H24: 400
A25: Chorale de la Police fribourgeoise | B25: Fribourg | H25: 10000
A26: Groupement Sportif de la Police Cantonale Vaudoise | B26: Vaud | I26: 2000 | M26: 1000
A27: Police cantonale section III Festival suisse des musiques de police 2023 | B27: Jura | M27: 7000
A28: FC police judiciaire | B28: Neuchâtel | O28: 630
A31: Interprofession de la Vigne et du Vin du Valais | B31: Valais | D31: 150000 | E31: 150000 | F31: 150000 | G31: 150000 | H31: 150000 | I31: 150000 | J31: 150000 | K31: 150000 | L31: 225000 | M31: 225000 | N31: 200000 | O31: 200000 | P31: 200000
A34: Athlétissima | B34: Vaud | D34: 60000 | E34: 120000 | F34: 55000 | G34: 5000 | H34: 60000 | I34: 70000 | J34: 70000 | K34: 108000 | L34: 90000 | M34: 70000 | N34: 92000 | O34: 140000 | P34: =88000+50000 -> 138000
A36: Fonds d’utilité publique du Gouvernement | B36: Jura | D36: 1260817 | E36: 1252335 | F36: 1234695 | G36: 1245834 | H36: 1275116 | I36: 1244451 | J36: 1227065 | K36: 1268887 | L36: 1200256.8 | M36: 1517719 | N36: 1107516 | O36: 1414345 | P36: 1660101
A37: Détail dispo | D37: non | E37: non | F37: non | G37: non | H37: non | I37: non | J37: non | K37: non | L37: oui | M37: part | N37: oui | O37: oui | P37: oui
A38: Associations à définir par le Gouvernement > Guerre en Ukraine | M38: 80000
A39: Marché-Concours national de chevaux - Prix du Gouvernement | M39: 3000 | N39: 3000 | O39: 3000 | P39: 3000
